Workbook
Name Slicer_Category1: #N/A
Name Slicer_Region: #N/A
Name Slicer_Region1: #N/A
Name Slicer_Segment: #N/A
Name Slicer_Sub_Category: #N/A

Sheet Raw Data
A1: Sales dataset of a leading superstrore in the USA for January 2017
A2: Order ID | B2: Order Date | C2: Customer ID | D2: Customer Name | E2: Segment | F2: City | G2: State | H2: Region | I2: Prod. ID | J2: Category | K2: Sub-Category | L2: Prod. Name | M2: Sales | N2: Quantity | O2: Discount | P2: Profit
A3: CA-2017-107503 | B3: 42736 | C3: GA-14725 | D3: Guy Armstrong | E3: Consumar | F3: Lorain | G3: Ohio | H3: East | I3: FUR-FU-10003878 | J3: Furniture | K3: Furnishings | L3: Linden 10" Round Wall Clock, Black | M3: 48.896 | N3: 4 | O3: 0.2 | P3: 8.5568
A4: CA-2017-144463 | B4: 42736 | C4: SC-20725 | D4: Steven Cartwright | E4: Consumar | F4: Los Angeles | G4: California | H4: West | I4: FUR-FU-10001215 | J4: Furniture | K4: Furnishings | L4: Howard Miller 11-1/2" Diameter Brentwood Wall Clock | M4: 474.43 | N4: 11 | O4: 0 | P4: 199.2606
A5: CA-2017-154466 | B5: 42736 | C5: DP-13390 | D5: Dennis Pardue | E5: Home Office | F5: Franklin | G5: Wisconsin | H5: Central | I5: OFF-BI-10002012 | J5: Office Supplies | K5: Binders | L5: Wilson Jones Easy Flow II Sheet Lifters | M5: 3.6 | N5: 2 | O5: 0 | P5: 1.728
A6: CA-2017-151750 | B6: 42736 | C6: JM-15250 | D6: Janet Martin | E6: Consumar | F6: Huntsville | G6: Texes | H6: Central | I6: OFF-ST-10002743 | J6: Office Supplies | K6: Storage | L6: SAFCO Boltless Steel Shelving | M6: 454.56 | N6: 5 | O6: 0.2 | P6: -107.958
A7: CA-2017-151750 | B7: 42736 | C7: JM-15250 | D7: Janet Martin | E7: Consumar | F7: Huntsville | G7: Texes | H7: Central | I7: FUR-FU-10002116 | J7: Furniture | K7: Furnishings | L7: Tenex Carpeted, Granite-Look or Clear Contemporary Contour Shape Chair Mats | M7: 141.42 | N7: 5 | O7: 0.6 | P7: -187.3815
A8: CA-2017-151750 | B8: 42736 | C8: JM-15250 | D8: Janet Martin | E8: Consumar | F8: Huntsville | G8: Texes | H8: Central | I8: FUR-CH-10003199 | J8: Furniture | K8: Chairs | L8: Office Star - Contemporary Task Swivel Chair | M8: 310.744 | N8: 4 | O8: 0.3 | P8: -26.6352
A9: CA-2017-151750 | B9: 42736 | C9: JM-15250 | D9: Janet Martin | E9: Consumar | F9: Huntsville | G9: Texes | H9: Central | I9: OFF-AR-10003158 | J9: Office Supplies | K9: Art | L9: Fluorescent Highlighters by Dixon | M9: 12.736 | N9: 4 | O9: 0.2 | P9: 2.2288
A10: CA-2017-151750 | B10: 42736 | C10: JM-15250 | D10: Janet Martin | E10: Consumar | F10: Huntsville | G10: Texes | H10: Central | I10: OFF-BI-10000301 | J10: Office Supplies | K10: Binders | L10: GBC Instant Report Kit | M10: 6.47 | N10: 5 | O10: 0.8 | P10: -9.705
A11: CA-2017-151750 | B11: 42736 | C11: JM-15250 | D11: Janet Martin | E11: Consumar | F11: Huntsville | G11: Texes | H11: Central | I11: OFF-BI-10000343 | J11: Office Supplies | K11: Binders | L11: Pressboard Covers with Storage Hooks, 9 1/2" x 11", Light Blue | M11: 13.748 | N11: 14 | O11: 0.8 | P11: -22.6842
A12: CA-2017-151750 | B12: 42736 | C12: JM-15250 | D12: Janet Martin | E12: Consumar | F12: Huntsville | G12: Texes | H12: Central | I12: OFF-AP-10004708 | J12: Office Supplies | K12: Appliances | L12: Fellowes Superior 10 Outlet Split Surge Protector | M12: 15.224 | N12: 2 | O12: 0.8 | P12: -38.8212
A13: CA-2017-113481 | B13: 42737 | C13: AS-10045 | D13: Aaron Smayling | E13: Corporate | F13: Jacksonville | G13: North Carolina | H13: South | I13: TEC-MA-10002178 | J13: Technology | K13: Machines | L13: Cisco CP-7937G Unified IP Conference Station Phone | M13: 695.7 | N13: 2 | O13: 0.5 | P13: -27.828
A14: CA-2017-113481 | B14: 42737 | C14: AS-10045 | D14: Aaron Smayling | E14: Corporate | F14: Jacksonville | G14: North Carolina | H14: South | I14: OFF-BI-10003694 | J14: Office Supplies | K14: Binders | L14: Avery 3 1/2" Diskette Storage Pages, 10/Pack | M14: 15.66 | N14: 5 | O14: 0.7 | P14: -12.528
... A157: CA-2017-157273 | B157: 42765 | C157: SZ-20035 | D157: Sam Zeldin | E157: Home Office | F157: Seattle | G157: Washington | H157: West | I157: TEC-PH-10002275 | J157: Technology | K157: Phones | L157: Mitel 5320 IP Phone VoIP phone | M157: 604.768 | N157: 4 | O157: 0.2 | P157: 60.4768

Sheet Cleaned Data
A1: Sales dataset of a leading superstrore in the USA for January 2017
A2: Order ID | B2: Order Date | C2: Customer ID | D2: Customer Name | E2: Segment | F2: City | G2: State | H2: Region | I2: Product ID | J2: Category | K2: Sub-Category | L2: Product Name | M2: Sales | N2: Quantity | O2: Discount | P2: Profit
A3: CA-2017-107503 | B3: 01/01/2017 | C3: GA-14725 | D3: Guy Armstrong | E3: Consumer | F3: Lorain | G3: Ohio | H3: East | I3: FUR-FU-10003878 | J3: Furniture | K3: Furnishings | L3: Linden 10" Round Wall Clock, Black | M3: 48.896 | N3: 4 | O3: 0.2 | P3: 8.5568
A4: CA-2017-144463 | B4: 01/01/2017 | C4: SC-20725 | D4: Steven Cartwright | E4: Consumer | F4: Los Angeles | G4: California | H4: West | I4: FUR-FU-10001215 | J4: Furniture | K4: Furnishings | L4: Howard Miller 11-1/2" Diameter Brentwood Wall Clock | M4: 474.43 | N4: 11 | O4: 0 | P4: 199.2606
A5: CA-2017-154466 | B5: 01/01/2017 | C5: DP-13390 | D5: Dennis Pardue | E5: Home Office | F5: Franklin | G5: Wisconsin | H5: Central | I5: OFF-BI-10002012 | J5: Office Supplies | K5: Binders | L5: Wilson Jones Easy Flow II Sheet Lifters | M5: 3.6 | N5: 2 | O5: 0 | P5: 1.728
A6: CA-2017-151750 | B6: 01/01/2017 | C6: JM-15250 | D6: Janet Martin | E6: Consumer | F6: Huntsville | G6: Texas | H6: Central | I6: OFF-ST-10002743 | J6: Office Supplies | K6: Storage | L6: SAFCO Boltless Steel Shelving | M6: 454.56 | N6: 5 | O6: 0.2 | P6: -107.958
A7: CA-2017-151750 | B7: 01/01/2017 | C7: JM-15250 | D7: Janet Martin | E7: Consumer | F7: Huntsville | G7: Texas | H7: Central | I7: FUR-FU-10002116 | J7: Furniture | K7: Furnishings | L7: Tenex Carpeted, Granite-Look or Clear Contemporary Contour Shape Chair Mats | M7: 141.42 | N7: 5 | O7: 0.6 | P7: -187.3815
A8: CA-2017-151750 | B8: 01/01/2017 | C8: JM-15250 | D8: Janet Martin | E8: Consumer | F8: Huntsville | G8: Texas | H8: Central | I8: FUR-CH-10003199 | J8: Furniture | K8: Chairs | L8: Office Star - Contemporary Task Swivel Chair | M8: 310.744 | N8: 4 | O8: 0.3 | P8: -26.6352
A9: CA-2017-151750 | B9: 01/01/2017 | C9: JM-15250 | D9: Janet Martin | E9: Consumer | F9: Huntsville | G9: Texas | H9: Central | I9: OFF-AR-10003158 | J9: Office Supplies | K9: Art | L9: Fluorescent Highlighters by Dixon | M9: 12.736 | N9: 4 | O9: 0.2 | P9: 2.2288
A10: CA-2017-151750 | B10: 01/01/2017 | C10: JM-15250 | D10: Janet Martin | E10: Consumer | F10: Huntsville | G10: Texas | H10: Central | I10: OFF-BI-10000301 | J10: Office Supplies | K10: Binders | L10: GBC Instant Report Kit | M10: 6.47 | N10: 5 | O10: 0.8 | P10: -9.705
A11: CA-2017-151750 | B11: 01/01/2017 | C11: JM-15250 | D11: Janet Martin | E11: Consumer | F11: Huntsville | G11: Texas | H11: Central | I11: OFF-BI-10000343 | J11: Office Supplies | K11: Binders | L11: Pressboard Covers with Storage Hooks, 9 1/2" x 11", Light Blue | M11: 13.748 | N11: 14 | O11: 0.8 | P11: -22.6842
A12: CA-2017-151750 | B12: 01/01/2017 | C12: JM-15250 | D12: Janet Martin | E12: Consumer | F12: Huntsville | G12: Texas | H12: Central | I12: OFF-AP-10004708 | J12: Office Supplies | K12: Appliances | L12: Fellowes Superior 10 Outlet Split Surge Protector | M12: 15.224 | N12: 2 | O12: 0.8 | P12: -38.8212
A13: CA-2017-113481 | B13: 02/01/2017 | C13: AS-10045 | D13: Aaron Smayling | E13: Corporate | F13: Jacksonville | G13: North Carolina | H13: South | I13: TEC-MA-10002178 | J13: Technology | K13: Machines | L13: Cisco CP-7937G Unified IP Conference Station Phone | M13: 695.7 | N13: 2 | O13: 0.5 | P13: -27.828
A14: CA-2017-113481 | B14: 02/01/2017 | C14: AS-10045 | D14: Aaron Smayling | E14: Corporate | F14: Jacksonville | G14: North Carolina | H14: South | I14: OFF-BI-10003694 | J14: Office Supplies | K14: Binders | L14: Avery 3 1/2" Diskette Storage Pages, 10/Pack | M14: 15.66 | N14: 5 | O14: 0.7 | P14: -12.528
... A157: CA-2017-157273 | B157: 30/01/2017 | C157: SZ-20035 | D157: Sam Zeldin | E157: Home Office | F157: Seattle | G157: Washington | H157: West | I157: TEC-PH-10002275 | J157: Technology | K157: Phones | L157: Mitel 5320 IP Phone VoIP phone | M157: 604.768 | N157: 4 | O157: 0.2 | P157: 60.4768

Sheet Customers
A1: Customers Reference Table
A2: Customer ID | B2: Customer Name | C2: Segment | D2: City | E2: State | F2: Region
A3: GA-14725 | B3: Guy Armstrong | C3: Consumer | D3: Lorain | E3: Ohio | F3: East
A4: SC-20725 | B4: Steven Cartwright | C4: Consumer | D4: Los Angeles | E4: California | F4: West
A5: DP-13390 | B5: Dennis Pardue | C5: Home Office | D5: Franklin | E5: Wisconsin | F5: Central
A6: JM-15250 | B6: Janet Martin | C6: Consumer | D6: Huntsville | E6: Texas | F6: Central
A7: AS-10045 | B7: Aaron Smayling | C7: Corporate | D7: Jacksonville | E7: North Carolina | F7: South
A8: TS-21655 | B8: Trudy Schmidt | C8: Consumer | D8: El Paso | E8: Texas | F8: Central
A9: FW-14395 | B9: Fred Wasserman | C9: Corporate | D9: Los Angeles | E9: California | F9: West
A10: DL-13315 | B10: Delfina Latchford | C10: Consumer | D10: Rancho Cucamonga | E10: California | F10: West
A11: CM-12385 | B11: Christopher Martinez | C11: Consumer | D11: San Francisco | E11: California | F11: West
A12: BW-11110 | B12: Bart Watters | C12: Corporate | D12: Detroit | E12: Michigan | F12: Central
A13: TS-21085 | B13: Thais Sissman | C13: Consumer | D13: Ormond Beach | E13: Florida | F13: South
... A69: SZ-20035 | B69: Sam Zeldin | C69: Home Office | D69: Seattle | E69: Washington | F69: West

Sheet Orders
A1: Orders Reference Table
A2: Order ID | B2: Order Date | C2: Customer ID | D2: Customer Name | E2: Region
A3: CA-2017-107503 | B3: 01/01/2017 | C3: GA-14725 | D3: =_xlfn.XLOOKUP(C4,'Cleaned Data'!C3:C157,'Cleaned Data'!D3:D157) -> Steven Cartwright | E3: =_xlfn.XLOOKUP(A3,'Cleaned Data'!A3:A157,'Cleaned Data'!H3:H157) -> East
A4: CA-2017-144463 | B4: 01/01/2017 | C4: SC-20725 | D4: =_xlfn.XLOOKUP(C5,'Cleaned Data'!C4:C158,'Cleaned Data'!D4:D158) -> Dennis Pardue | E4: =_xlfn.XLOOKUP(A4,'Cleaned Data'!A4:A158,'Cleaned Data'!H4:H158) -> West
A5: CA-2017-154466 | B5: 01/01/2017 | C5: DP-13390 | D5: =_xlfn.XLOOKUP(C6,'Cleaned Data'!C5:C159,'Cleaned Data'!D5:D159) -> Janet Martin | E5: =_xlfn.XLOOKUP(A5,'Cleaned Data'!A5:A159,'Cleaned Data'!H5:H159) -> Central
A6: CA-2017-151750 | B6: 01/01/2017 | C6: JM-15250 | D6: =_xlfn.XLOOKUP(C7,'Cleaned Data'!C6:C160,'Cleaned Data'!D6:D160) -> Aaron Smayling | E6: =_xlfn.XLOOKUP(A6,'Cleaned Data'!A6:A160,'Cleaned Data'!H6:H160) -> Central
A7: CA-2017-113481 | B7: 02/01/2017 | C7: AS-10045 | D7: =_xlfn.XLOOKUP(C8,'Cleaned Data'!C13:C167,'Cleaned Data'!D13:D167) -> Trudy Schmidt | E7: =_xlfn.XLOOKUP(A7,'Cleaned Data'!A13:A167,'Cleaned Data'!H13:H167) -> South
A8: CA-2017-147207 | B8: 02/01/2017 | C8: TS-21655 | D8: =_xlfn.XLOOKUP(C9,'Cleaned Data'!C16:C170,'Cleaned Data'!D16:D170) -> Fred Wasserman | E8: =_xlfn.XLOOKUP(A8,'Cleaned Data'!A16:A170,'Cleaned Data'!H16:H170) -> Central
A9: CA-2017-118668 | B9: 02/01/2017 | C9: FW-14395 | D9: =_xlfn.XLOOKUP(C10,'Cleaned Data'!C20:C174,'Cleaned Data'!D20:D174) -> Delfina Latchford | E9: =_xlfn.XLOOKUP(A9,'Cleaned Data'!A20:A174,'Cleaned Data'!H20:H174) -> West
A10: US-2017-114034 | B10: 03/01/2017 | C10: DL-13315 | D10: =_xlfn.XLOOKUP(C11,'Cleaned Data'!C21:C175,'Cleaned Data'!D21:D175) -> Christopher Martinez | E10: =_xlfn.XLOOKUP(A10,'Cleaned Data'!A21:A175,'Cleaned Data'!H21:H175) -> West
A11: CA-2017-111738 | B11: 03/01/2017 | C11: CM-12385 | D11: =_xlfn.XLOOKUP(C12,'Cleaned Data'!C22:C176,'Cleaned Data'!D22:D176) -> Dennis Pardue | E11: =_xlfn.XLOOKUP(A11,'Cleaned Data'!A22:A176,'Cleaned Data'!H22:H176) -> West
A12: CA-2017-150931 | B12: 06/01/2017 | C12: DP-13390 | D12: =_xlfn.XLOOKUP(C13,'Cleaned Data'!C24:C178,'Cleaned Data'!D24:D178) -> Bart Watters | E12: =_xlfn.XLOOKUP(A12,'Cleaned Data'!A24:A178,'Cleaned Data'!H24:H178) -> South
A13: CA-2017-159366 | B13: 07/01/2017 | C13: BW-11110 | D13: =_xlfn.XLOOKUP(C14,'Cleaned Data'!C25:C179,'Cleaned Data'!D25:D179) -> Thais Sissman | E13: =_xlfn.XLOOKUP(A13,'Cleaned Data'!A25:A179,'Cleaned Data'!H25:H179) -> Central
A14: US-2017-168690 | B14: 07/01/2017 | C14: TS-21085 | D14: =_xlfn.XLOOKUP(C15,'Cleaned Data'!C26:C180,'Cleaned Data'!D26:D180) -> Jamie Frazer | E14: =_xlfn.XLOOKUP(A14,'Cleaned Data'!A26:A180,'Cleaned Data'!H26:H180) -> South
A15: US-2017-123862 | B15: 07/01/2017 | C15: JF-15190 | D15: =_xlfn.XLOOKUP(C16,'Cleaned Data'!C27:C181,'Cleaned Data'!D27:D181) -> Ricardo Sperren | E15: =_xlfn.XLOOKUP(A15,'Cleaned Data'!A27:A181,'Cleaned Data'!H27:H181) -> West
A16: CA-2017-115154 | B16: 08/01/2017 | C16: RS-19420 | D16: =_xlfn.XLOOKUP(C17,'Cleaned Data'!C31:C185,'Cleaned Data'!D31:D185) -> Beth Paige | E16: =_xlfn.XLOOKUP(A16,'Cleaned Data'!A31:A185,'Cleaned Data'!H31:H185) -> West
A17: CA-2017-154760 | B17: 09/01/2017 | C17: BP-11290 | D17: =_xlfn.XLOOKUP(C18,'Cleaned Data'!C32:C186,'Cleaned Data'!D32:D186) -> Dianna Arnett | E17: =_xlfn.XLOOKUP(A17,'Cleaned Data'!A32:A186,'Cleaned Data'!H32:H186) -> East
A18: US-2017-158512 | B18: 12/01/2017 | C18: DA-13450 | D18: =_xlfn.XLOOKUP(C19,'Cleaned Data'!C33:C187,'Cleaned Data'!D33:D187) -> Linda Southworth | E18: =_xlfn.XLOOKUP(A18,'Cleaned Data'!A33:A187,'Cleaned Data'!H33:H187) -> East
A19: CA-2017-108000 | B19: 12/01/2017 | C19: LS-16945 | D19: =_xlfn.XLOOKUP(C20,'Cleaned Data'!C35:C189,'Cleaned Data'!D35:D189) -> David Bremer | E19: =_xlfn.XLOOKUP(A19,'Cleaned Data'!A35:A189,'Cleaned Data'!H35:H189) -> West
A20: US-2017-148551 | B20: 12/01/2017 | C20: DB-13120 | D20: =_xlfn.XLOOKUP(C21,'Cleaned Data'!C36:C190,'Cleaned Data'!D36:D190) -> Cathy Prescott | E20: =_xlfn.XLOOKUP(A20,'Cleaned Data'!A36:A190,'Cleaned Data'!H36:H190) -> Central
A21: US-2017-167402 | B21: 13/01/2017 | C21: CP-12085 | D21: =_xlfn.XLOOKUP(C22,'Cleaned Data'!C37:C191,'Cleaned Data'!D37:D191) -> Rob Beeghly | E21: =_xlfn.XLOOKUP(A21,'Cleaned Data'!A37:A191,'Cleaned Data'!H37:H191) -> Central
A22: CA-2017-138779 | B22: 14/01/2017 | C22: RB-19570 | D22: =_xlfn.XLOOKUP(C23,'Cleaned Data'!C41:C195,'Cleaned Data'!D41:D195) -> Tracy Poddar | E22: =_xlfn.XLOOKUP(A22,'Cleaned Data'!A41:A195,'Cleaned Data'!H41:H195) -> South
A23: US-2017-106131 | B23: 14/01/2017 | C23: TP-21565 | D23: =_xlfn.XLOOKUP(C24,'Cleaned Data'!C43:C197,'Cleaned Data'!D43:D197) -> Brosina Hoffman | E23: =_xlfn.XLOOKUP(A23,'Cleaned Data'!A43:A197,'Cleaned Data'!H43:H197) -> West
A24: CA-2017-127306 | B24: 14/01/2017 | C24: BH-11710 | D24: =_xlfn.XLOOKUP(C25,'Cleaned Data'!C45:C199,'Cleaned Data'!D45:D199) -> Sean O'Donnell | E24: =_xlfn.XLOOKUP(A24,'Cleaned Data'!A45:A199,'Cleaned Data'!H45:H199) -> South
A25: CA-2017-149076 | B25: 14/01/2017 | C25: SO-20335 | D25: =_xlfn.XLOOKUP(C26,'Cleaned Data'!C50:C204,'Cleaned Data'!D50:D204) -> Hallie Redmond | E25: =_xlfn.XLOOKUP(A25,'Cleaned Data'!A50:A204,'Cleaned Data'!H50:H204) -> West
A26: CA-2017-113278 | B26: 14/01/2017 | C26: HR-14770 | D26: =_xlfn.XLOOKUP(C27,'Cleaned Data'!C51:C205,'Cleaned Data'!D51:D205) -> Robert Waldorf | E26: =_xlfn.XLOOKUP(A26,'Cleaned Data'!A51:A205,'Cleaned Data'!H51:H205) -> Central
A27: CA-2017-167752 | B27: 15/01/2017 | C27: RW-19690 | D27: =_xlfn.XLOOKUP(C28,'Cleaned Data'!C59:C213,'Cleaned Data'!D59:D213) -> Sanjit Chand | E27: =_xlfn.XLOOKUP(A27,'Cleaned Data'!A59:A213,'Cleaned Data'!H59:H213) -> East
A28: CA-2017-152961 | B28: 15/01/2017 | C28: SC-20095 | D28: =_xlfn.XLOOKUP(C29,'Cleaned Data'!C61:C215,'Cleaned Data'!D61:D215) -> Tonja Turnell | E28: =_xlfn.XLOOKUP(A28,'Cleaned Data'!A61:A215,'Cleaned Data'!H61:H215) -> East
A29: CA-2017-160934 | B29: 15/01/2017 | C29: TT-21460 | D29: =_xlfn.XLOOKUP(C30,'Cleaned Data'!C62:C216,'Cleaned Data'!D62:D216) -> Tim Brockman | E29: =_xlfn.XLOOKUP(A29,'Cleaned Data'!A62:A216,'Cleaned Data'!H62:H216) -> West
A30: US-2017-104661 | B30: 15/01/2017 | C30: TB-21250 | D30: =_xlfn.XLOOKUP(C31,'Cleaned Data'!C63:C217,'Cleaned Data'!D63:D217) -> Jack O'Briant | E30: =_xlfn.XLOOKUP(A30,'Cleaned Data'!A63:A217,'Cleaned Data'!H63:H217) -> Central
A31: CA-2017-125913 | B31: 16/01/2017 | C31: JO-15145 | D31: =_xlfn.XLOOKUP(C32,'Cleaned Data'!C67:C221,'Cleaned Data'!D67:D221) -> Andy Reiter | E31: =_xlfn.XLOOKUP(A31,'Cleaned Data'!A67:A221,'Cleaned Data'!H67:H221) -> West
A32: CA-2017-138289 | B32: 16/01/2017 | C32: AR-10540 | D32: =_xlfn.XLOOKUP(C33,'Cleaned Data'!C69:C223,'Cleaned Data'!D69:D223) -> Dan Lawera | E32: =_xlfn.XLOOKUP(A32,'Cleaned Data'!A69:A223,'Cleaned Data'!H69:H223) -> Central
A33: CA-2017-154718 | B33: 19/01/2017 | C33: DL-12865 | D33: =_xlfn.XLOOKUP(C34,'Cleaned Data'!C72:C226,'Cleaned Data'!D72:D226) -> Neola Schneider | E33: =_xlfn.XLOOKUP(A33,'Cleaned Data'!A72:A226,'Cleaned Data'!H72:H226) -> Central
A34: CA-2017-153045 | B34: 19/01/2017 | C34: NS-18505 | D34: =_xlfn.XLOOKUP(C35,'Cleaned Data'!C73:C227,'Cleaned Data'!D73:D227) -> Raymond Messe | E34: =_xlfn.XLOOKUP(A34,'Cleaned Data'!A73:A227,'Cleaned Data'!H73:H227) -> East
A35: US-2017-127292 | B35: 19/01/2017 | C35: RM-19375 | D35: =_xlfn.XLOOKUP(C36,'Cleaned Data'!C77:C231,'Cleaned Data'!D77:D231) -> Cynthia Voltz | E35: =_xlfn.XLOOKUP(A35,'Cleaned Data'!A77:A231,'Cleaned Data'!H77:H231) -> East
A36: CA-2017-157252 | B36: 20/01/2017 | C36: CV-12805 | D36: =_xlfn.XLOOKUP(C37,'Cleaned Data'!C81:C235,'Cleaned Data'!D81:D235) -> Thea Hendricks | E36: =_xlfn.XLOOKUP(A36,'Cleaned Data'!A81:A235,'Cleaned Data'!H81:H235) -> East
A37: CA-2017-161809 | B37: 20/01/2017 | C37: TH-21100 | D37: =_xlfn.XLOOKUP(C38,'Cleaned Data'!C82:C236,'Cleaned Data'!D82:D236) -> Tamara Manning | E37: =_xlfn.XLOOKUP(A37,'Cleaned Data'!A82:A236,'Cleaned Data'!H82:H236) -> West
A38: CA-2017-144589 | B38: 20/01/2017 | C38: TM-21010 | D38: =_xlfn.XLOOKUP(C39,'Cleaned Data'!C83:C237,'Cleaned Data'!D83:D237) -> Jeremy Farry | E38: =_xlfn.XLOOKUP(A38,'Cleaned Data'!A83:A237,'Cleaned Data'!H83:H237) -> West
A39: US-2017-120649 | B39: 20/01/2017 | C39: JF-15490 | D39: =_xlfn.XLOOKUP(C40,'Cleaned Data'!C85:C239,'Cleaned Data'!D85:D239) -> Maris LaWare | E39: =_xlfn.XLOOKUP(A39,'Cleaned Data'!A85:A239,'Cleaned Data'!H85:H239) -> East
A40: CA-2017-152079 | B40: 20/01/2017 | C40: ML-17410 | D40: =_xlfn.XLOOKUP(C41,'Cleaned Data'!C86:C240,'Cleaned Data'!D86:D240) -> Darrin Sayre | E40: =_xlfn.XLOOKUP(A40,'Cleaned Data'!A86:A240,'Cleaned Data'!H86:H240) -> Central
...

Sheet Products
A1: Products Reference Table
A2: Product ID | B2: Category | C2: Sub-Category | D2: Product Name
A3: FUR-FU-10003878 | B3: Furniture | C3: Furnishings | D3: Linden 10" Round Wall Clock, Black
A4: FUR-FU-10001215 | B4: Furniture | C4: Furnishings | D4: Howard Miller 11-1/2" Diameter Brentwood Wall Clock
A5: OFF-BI-10002012 | B5: Office Supplies | C5: Binders | D5: Wilson Jones Easy Flow II Sheet Lifters
A6: OFF-ST-10002743 | B6: Office Supplies | C6: Storage | D6: SAFCO Boltless Steel Shelving
A7: FUR-FU-10002116 | B7: Furniture | C7: Furnishings | D7: Tenex Carpeted, Granite-Look or Clear Contemporary Contour Shape Chair Mats
A8: FUR-CH-10003199 | B8: Furniture | C8: Chairs | D8: Office Star - Contemporary Task Swivel Chair
A9: OFF-AR-10003158 | B9: Office Supplies | C9: Art | D9: Fluorescent Highlighters by Dixon
A10: OFF-BI-10000301 | B10: Office Supplies | C10: Binders | D10: GBC Instant Report Kit
A11: OFF-BI-10000343 | B11: Office Supplies | C11: Binders | D11: Pressboard Covers with Storage Hooks, 9 1/2" x 11", Light Blue
A12: OFF-AP-10004708 | B12: Office Supplies | C12: Appliances | D12: Fellowes Superior 10 Outlet Split Surge Protector
A13: TEC-MA-10002178 | B13: Technology | C13: Machines | D13: Cisco CP-7937G Unified IP Conference Station Phone
... A154: TEC-PH-10002275 | B154: Technology | C154: Phones | D154: Mitel 5320 IP Phone VoIP phone

Sheet Order Details
A1: Order Details Reference Table
A2: Order ID | B2: Product ID | C2: Sales | D2: Quantity | E2: Discount | F2: Profit | G2: Product Name | H2: Category | I2: Sub-Category | J2: Region | K2: Segment
A3: CA-2017-107503 | B3: FUR-FU-10003878 | C3: 48.896 | D3: 4 | E3: 0.2 | F3: 8.5568 | G3: =_xlfn.XLOOKUP(B3,'Cleaned Data'!I3:I157,'Cleaned Data'!L3:L157) -> Linden 10" Round Wall Clock, Black | H3: =_xlfn.XLOOKUP(B3,'Cleaned Data'!I3:I157,'Cleaned Data'!J3:J157) -> Furniture | I3: =_xlfn.XLOOKUP(B3,'Cleaned Data'!I3:I157,'Cleaned Data'!K3:K157) -> Furnishings | J3: =_xlfn.XLOOKUP(B3,'Cleaned Data'!I3:I157,'Cleaned Data'!H3:H157) -> East | K3: =_xlfn.XLOOKUP(B3,'Cleaned Data'!I3:I157,'Cleaned Data'!E3:E157) -> Consumer
A4: CA-2017-144463 | B4: FUR-FU-10001215 | C4: 474.43 | D4: 11 | E4: 0 | F4: 199.2606 | G4: =_xlfn.XLOOKUP(B4,'Cleaned Data'!I4:I158,'Cleaned Data'!L4:L158) -> Howard Miller 11-1/2" Diameter Brentwood Wall Clock | H4: =_xlfn.XLOOKUP(B4,'Cleaned Data'!I4:I158,'Cleaned Data'!J4:J158) -> Furniture | I4: =_xlfn.XLOOKUP(B4,'Cleaned Data'!I4:I158,'Cleaned Data'!K4:K158) -> Furnishings | J4: =_xlfn.XLOOKUP(B4,'Cleaned Data'!I4:I158,'Cleaned Data'!H4:H158) -> West | K4: =_xlfn.XLOOKUP(B4,'Cleaned Data'!I4:I158,'Cleaned Data'!E4:E158) -> Consumer
A5: CA-2017-154466 | B5: OFF-BI-10002012 | C5: 3.6 | D5: 2 | E5: 0 | F5: 1.728 | G5: =_xlfn.XLOOKUP(B5,'Cleaned Data'!I5:I159,'Cleaned Data'!L5:L159) -> Wilson Jones Easy Flow II Sheet Lifters | H5: =_xlfn.XLOOKUP(B5,'Cleaned Data'!I5:I159,'Cleaned Data'!J5:J159) -> Office Supplies | I5: =_xlfn.XLOOKUP(B5,'Cleaned Data'!I5:I159,'Cleaned Data'!K5:K159) -> Binders | J5: =_xlfn.XLOOKUP(B5,'Cleaned Data'!I5:I159,'Cleaned Data'!H5:H159) -> Central | K5: =_xlfn.XLOOKUP(B5,'Cleaned Data'!I5:I159,'Cleaned Data'!E5:E159) -> Home Office
A6: CA-2017-151750 | B6: OFF-ST-10002743 | C6: 454.56 | D6: 5 | E6: 0.2 | F6: -107.958 | G6: =_xlfn.XLOOKUP(B6,'Cleaned Data'!I6:I160,'Cleaned Data'!L6:L160) -> SAFCO Boltless Steel Shelving | H6: =_xlfn.XLOOKUP(B6,'Cleaned Data'!I6:I160,'Cleaned Data'!J6:J160) -> Office Supplies | I6: =_xlfn.XLOOKUP(B6,'Cleaned Data'!I6:I160,'Cleaned Data'!K6:K160) -> Storage | J6: =_xlfn.XLOOKUP(B6,'Cleaned Data'!I6:I160,'Cleaned Data'!H6:H160) -> Central | K6: =_xlfn.XLOOKUP(B6,'Cleaned Data'!I6:I160,'Cleaned Data'!E6:E160) -> Consumer
A7: CA-2017-151750 | B7: FUR-FU-10002116 | C7: 141.42 | D7: 5 | E7: 0.6 | F7: -187.3815 | G7: =_xlfn.XLOOKUP(B7,'Cleaned Data'!I7:I161,'Cleaned Data'!L7:L161) -> Tenex Carpeted, Granite-Look or Clear Contemporary Contour Shape Chair Mats | H7: =_xlfn.XLOOKUP(B7,'Cleaned Data'!I7:I161,'Cleaned Data'!J7:J161) -> Furniture | I7: =_xlfn.XLOOKUP(B7,'Cleaned Data'!I7:I161,'Cleaned Data'!K7:K161) -> Furnishings | J7: =_xlfn.XLOOKUP(B7,'Cleaned Data'!I7:I161,'Cleaned Data'!H7:H161) -> Central | K7: =_xlfn.XLOOKUP(B7,'Cleaned Data'!I7:I161,'Cleaned Data'!E7:E161) -> Consumer
A8: CA-2017-151750 | B8: FUR-CH-10003199 | C8: 310.744 | D8: 4 | E8: 0.3 | F8: -26.6352 | G8: =_xlfn.XLOOKUP(B8,'Cleaned Data'!I8:I162,'Cleaned Data'!L8:L162) -> Office Star - Contemporary Task Swivel Chair | H8: =_xlfn.XLOOKUP(B8,'Cleaned Data'!I8:I162,'Cleaned Data'!J8:J162) -> Furniture | I8: =_xlfn.XLOOKUP(B8,'Cleaned Data'!I8:I162,'Cleaned Data'!K8:K162) -> Chairs | J8: =_xlfn.XLOOKUP(B8,'Cleaned Data'!I8:I162,'Cleaned Data'!H8:H162) -> Central | K8: =_xlfn.XLOOKUP(B8,'Cleaned Data'!I8:I162,'Cleaned Data'!E8:E162) -> Consumer
A9: CA-2017-151750 | B9: OFF-AR-10003158 | C9: 12.736 | D9: 4 | E9: 0.2 | F9: 2.2288 | G9: =_xlfn.XLOOKUP(B9,'Cleaned Data'!I9:I163,'Cleaned Data'!L9:L163) -> Fluorescent Highlighters by Dixon | H9: =_xlfn.XLOOKUP(B9,'Cleaned Data'!I9:I163,'Cleaned Data'!J9:J163) -> Office Supplies | I9: =_xlfn.XLOOKUP(B9,'Cleaned Data'!I9:I163,'Cleaned Data'!K9:K163) -> Art | J9: =_xlfn.XLOOKUP(B9,'Cleaned Data'!I9:I163,'Cleaned Data'!H9:H163) -> Central | K9: =_xlfn.XLOOKUP(B9,'Cleaned Data'!I9:I163,'Cleaned Data'!E9:E163) -> Consumer
A10: CA-2017-151750 | B10: OFF-BI-10000301 | C10: 6.47 | D10: 5 | E10: 0.8 | F10: -9.705 | G10: =_xlfn.XLOOKUP(B10,'Cleaned Data'!I10:I164,'Cleaned Data'!L10:L164) -> GBC Instant Report Kit | H10: =_xlfn.XLOOKUP(B10,'Cleaned Data'!I10:I164,'Cleaned Data'!J10:J164) -> Office Supplies | I10: =_xlfn.XLOOKUP(B10,'Cleaned Data'!I10:I164,'Cleaned Data'!K10:K164) -> Binders | J10: =_xlfn.XLOOKUP(B10,'Cleaned Data'!I10:I164,'Cleaned Data'!H10:H164) -> Central | K10: =_xlfn.XLOOKUP(B10,'Cleaned Data'!I10:I164,'Cleaned Data'!E10:E164) -> Consumer
A11: CA-2017-151750 | B11: OFF-BI-10000343 | C11: 13.748 | D11: 14 | E11: 0.8 | F11: -22.6842 | G11: =_xlfn.XLOOKUP(B11,'Cleaned Data'!I11:I165,'Cleaned Data'!L11:L165) -> Pressboard Covers with Storage Hooks, 9 1/2" x 11", Light Blue | H11: =_xlfn.XLOOKUP(B11,'Cleaned Data'!I11:I165,'Cleaned Data'!J11:J165) -> Office Supplies | I11: =_xlfn.XLOOKUP(B11,'Cleaned Data'!I11:I165,'Cleaned Data'!K11:K165) -> Binders | J11: =_xlfn.XLOOKUP(B11,'Cleaned Data'!I11:I165,'Cleaned Data'!H11:H165) -> Central | K11: =_xlfn.XLOOKUP(B11,'Cleaned Data'!I11:I165,'Cleaned Data'!E11:E165) -> Consumer
A12: CA-2017-151750 | B12: OFF-AP-10004708 | C12: 15.224 | D12: 2 | E12: 0.8 | F12: -38.8212 | G12: =_xlfn.XLOOKUP(B12,'Cleaned Data'!I12:I166,'Cleaned Data'!L12:L166) -> Fellowes Superior 10 Outlet Split Surge Protector | H12: =_xlfn.XLOOKUP(B12,'Cleaned Data'!I12:I166,'Cleaned Data'!J12:J166) -> Office Supplies | I12: =_xlfn.XLOOKUP(B12,'Cleaned Data'!I12:I166,'Cleaned Data'!K12:K166) -> Appliances | J12: =_xlfn.XLOOKUP(B12,'Cleaned Data'!I12:I166,'Cleaned Data'!H12:H166) -> Central | K12: =_xlfn.XLOOKUP(B12,'Cleaned Data'!I12:I166,'Cleaned Data'!E12:E166) -> Consumer
A13: CA-2017-113481 | B13: TEC-MA-10002178 | C13: 695.7 | D13: 2 | E13: 0.5 | F13: -27.828 | G13: =_xlfn.XLOOKUP(B13,'Cleaned Data'!I13:I167,'Cleaned Data'!L13:L167) -> Cisco CP-7937G Unified IP Conference Station Phone | H13: =_xlfn.XLOOKUP(B13,'Cleaned Data'!I13:I167,'Cleaned Data'!J13:J167) -> Technology | I13: =_xlfn.XLOOKUP(B13,'Cleaned Data'!I13:I167,'Cleaned Data'!K13:K167) -> Machines | J13: =_xlfn.XLOOKUP(B13,'Cleaned Data'!I13:I167,'Cleaned Data'!H13:H167) -> South | K13: =_xlfn.XLOOKUP(B13,'Cleaned Data'!I13:I167,'Cleaned Data'!E13:E167) -> Corporate
A14: CA-2017-113481 | B14: OFF-BI-10003694 | C14: 15.66 | D14: 5 | E14: 0.7 | F14: -12.528 | G14: =_xlfn.XLOOKUP(B14,'Cleaned Data'!I14:I168,'Cleaned Data'!L14:L168) -> Avery 3 1/2" Diskette Storage Pages, 10/Pack | H14: =_xlfn.XLOOKUP(B14,'Cleaned Data'!I14:I168,'Cleaned Data'!J14:J168) -> Office Supplies | I14: =_xlfn.XLOOKUP(B14,'Cleaned Data'!I14:I168,'Cleaned Data'!K14:K168) -> Binders | J14: =_xlfn.XLOOKUP(B14,'Cleaned Data'!I14:I168,'Cleaned Data'!H14:H168) -> South | K14: =_xlfn.XLOOKUP(B14,'Cleaned Data'!I14:I168,'Cleaned Data'!E14:E168) -> Corporate
... A157: CA-2017-157273 | B157: TEC-PH-10002275 | C157: 604.768 | D157: 4 | E157: 0.2 | F157: 60.4768 | G157: =_xlfn.XLOOKUP(B157,'Cleaned Data'!I157:I311,'Cleaned Data'!L157:L311) -> Mitel 5320 IP Phone VoIP phone | H157: =_xlfn.XLOOKUP(B157,'Cleaned Data'!I157:I311,'Cleaned Data'!J157:J311) -> Technology | I157: =_xlfn.XLOOKUP(B157,'Cleaned Data'!I157:I311,'Cleaned Data'!K157:K311) -> Phones | J157: =_xlfn.XLOOKUP(B157,'Cleaned Data'!I157:I311,'Cleaned Data'!H157:H311) -> West | K157: =_xlfn.XLOOKUP(B157,'Cleaned Data'!I157:I311,'Cleaned Data'!E157:E311) -> Home Office

Sheet Calculations
A1: Calculations by Region
A2: Region | B2: Sales | C2: Discounts | D2: Profit | E2: Quantity | F2: Number of Orders | H2: Profit Margin | J2: Average Order Value
A3: East | B3: =SUMIFS('Order Details'!C3:C157,'Order Details'!J3:J157,Calculations!A3) -> 5383.284 | C3: =SUMIFS('Order Details'!E3:E157,'Order Details'!J3:J157,Calculations!A3) -> 3.5 | D3: =SUMIFS('Order Details'!F3:F157,'Order Details'!J3:J157,Calculations!A3) -> 355.8694 | E3: =SUMIFS('Order Details'!D3:D157,'Order Details'!J3:J157,Calculations!A3) -> 76 | F3: =COUNTIFS(Orders!E3:E157,Calculations!A3) -> 14 | H3: =D7/B7 -> 0.16238836 | J3: =B7/F7 -> 637.26629
A4: West | B4: =SUMIFS('Order Details'!C3:C157,'Order Details'!J3:J157,A4) -> 12081.844 | C4: =SUMIFS('Order Details'!E3:E157,'Order Details'!J3:J157,A4) -> 4.1 | D4: =SUMIFS('Order Details'!F3:F157,'Order Details'!J3:J157,A4) -> 3208.3329 | E4: =SUMIFS('Order Details'!D3:D157,'Order Details'!J3:J157,A4) -> 208 | F4: =COUNTIFS(Orders!E3:E157,A4) -> 24
A5: Central | B5: =SUMIFS('Order Details'!C3:C157,'Order Details'!J3:J157,A5) -> 21690.656 | C5: =SUMIFS('Order Details'!E3:E157,'Order Details'!J3:J157,A5) -> 11.3 | D5: =SUMIFS('Order Details'!F3:F157,'Order Details'!J3:J157,A5) -> 2865.9345 | E5: =SUMIFS('Order Details'!D3:D157,'Order Details'!J3:J157,A5) -> 224 | F5: =COUNTIFS(Orders!E3:E157,A5) -> 21
A6: South | B6: =SUMIFS('Order Details'!C3:C157,'Order Details'!J3:J157,A6) -> 4815.59 | C6: =SUMIFS('Order Details'!E3:E157,'Order Details'!J3:J157,A6) -> 6.1 | D6: =SUMIFS('Order Details'!F3:F157,'Order Details'!J3:J157,A6) -> 710.3023 | E6: =SUMIFS('Order Details'!D3:D157,'Order Details'!J3:J157,A6) -> 89 | F6: =COUNTIFS(Orders!E3:E157,A6) -> 10
A7: Total | B7: =SUM(B3:B6) -> 43971.374 | C7: =SUM(C3:C6) -> 25 | D7: =SUM(D3:D6) -> 7140.4391 | E7: =SUM(E3:E6) -> 597 | F7: =SUM(F3:F6) -> 69
A9: Calculations by Customer Segment
A10: Segment | B10: Sales | C10: Discounts | D10: Profit | E10: Quantity | F10: Number of Customers
A11: Consumer | B11: =SUMIFS('Order Details'!C3:C157,'Order Details'!K3:K157,Calculations!A11) -> 23211.841 | C11: =SUMIFS('Order Details'!E3:E157,'Order Details'!K3:K157,Calculations!A11) -> 17.4 | D11: =SUMIFS('Order Details'!F3:F157,'Order Details'!K3:K157,Calculations!A11) -> 4679.951 | E11: =SUMIFS('Order Details'!D3:D157,'Order Details'!K3:K157,Calculations!A11) -> 314 | F11: =COUNTIFS(Customers!C3:C69,Calculations!A11) -> 38
A12: Home Office | B12: =SUMIFS('Order Details'!C3:C157,'Order Details'!K3:K157,A12) -> 8538.301 | C12: =SUMIFS('Order Details'!E3:E157,'Order Details'!K3:K157,A12) -> 2.9 | D12: =SUMIFS('Order Details'!F3:F157,'Order Details'!K3:K157,A12) -> 2413.9002 | E12: =SUMIFS('Order Details'!D3:D157,'Order Details'!K3:K157,A12) -> 147 | F12: =COUNTIFS(Customers!C3:C69,A12) -> 13
A13: Corporate | B13: =SUMIFS('Order Details'!C3:C157,'Order Details'!K3:K157,A13) -> 12221.232 | C13: =SUMIFS('Order Details'!E3:E157,'Order Details'!K3:K157,A13) -> 4.7 | D13: =SUMIFS('Order Details'!F3:F157,'Order Details'!K3:K157,A13) -> 46.5879 | E13: =SUMIFS('Order Details'!D3:D157,'Order Details'!K3:K157,A13) -> 136 | F13: =COUNTIFS(Customers!C3:C69,A13) -> 16
A14: Total | B14: =SUM(B11:B13) -> 43971.374 | C14: =SUM(C11:C13) -> 25 | D14: =SUM(D11:D13) -> 7140.4391 | E14: =SUM(E11:E13) -> 597 | F14: =SUM(F11:F13) -> 67
A16: Calculations by Product Category
A17: Category | B17: Sales | C17: Discounts | D17: Profit | E17: Quantity | F17: Products Sold
A18: Furniture | B18: =SUMIFS('Order Details'!C3:C157,'Order Details'!H3:H157,Calculations!A18) -> 5964.032 | C18: =SUMIFS('Order Details'!E3:E157,'Order Details'!H3:H157,Calculations!A18) -> 3.1 | D18: =SUMIFS('Order Details'!F3:F157,'Order Details'!H3:H157,Calculations!A18) -> -39.4402 | E18: =SUMIFS('Order Details'!D3:D157,'Order Details'!H3:H157,Calculations!A18) -> 86 | F18: =COUNTIFS(Products!B3:B154,Calculations!A18) -> 24
A19: Office Supplies | B19: =SUMIFS('Order Details'!C3:C157,'Order Details'!H3:H157,A19) -> 21274.289 | C19: =SUMIFS('Order Details'!E3:E157,'Order Details'!H3:H157,A19) -> 17.8 | D19: =SUMIFS('Order Details'!F3:F157,'Order Details'!H3:H157,A19) -> 3260.4467 | E19: =SUMIFS('Order Details'!D3:D157,'Order Details'!H3:H157,A19) -> 395 | F19: =COUNTIFS(Products!B3:B154,A19) -> 98
A20: Technology | B20: =SUMIFS('Order Details'!C3:C157,'Order Details'!H3:H157,A20) -> 16733.053 | C20: =SUMIFS('Order Details'!E3:E157,'Order Details'!H3:H157,A20) -> 4.1 | D20: =SUMIFS('Order Details'!F3:F157,'Order Details'!H3:H157,A20) -> 3919.4326 | E20: =SUMIFS('Order Details'!D3:D157,'Order Details'!H3:H157,A20) -> 116 | F20: =COUNTIFS(Products!B3:B154,A20) -> 30
A21: Total | B21: =SUM(B18:B20) -> 43971.374 | C21: =SUM(C18:C20) -> 25 | D21: =SUM(D18:D20) -> 7140.4391 | E21: =SUM(E18:E20) -> 597 | F21: =SUM(F18:F20) -> 152

Sheet Conditional Formatting
A1: Conditional Formatting of Order Details Table
A2: Order ID | B2: Product ID | C2: Sales | D2: Quantity | E2: Discount | F2: Profit
A3: CA-2017-107503 | B3: FUR-FU-10003878 | C3: 48.896 | D3: 4 | E3: 0.2 | F3: 8.5568 | H3: Average Profit
A4: CA-2017-144463 | B4: FUR-FU-10001215 | C4: 474.43 | D4: 11 | E4: 0 | F4: 199.2606 | H4: =AVERAGE(F3:F157) -> 46.067349
A5: CA-2017-154466 | B5: OFF-BI-10002012 | C5: 3.6 | D5: 2 | E5: 0 | F5: 1.728
A6: CA-2017-151750 | B6: OFF-ST-10002743 | C6: 454.56 | D6: 5 | E6: 0.2 | F6: -107.958
A7: CA-2017-151750 | B7: FUR-FU-10002116 | C7: 141.42 | D7: 5 | E7: 0.6 | F7: -187.3815
A8: CA-2017-151750 | B8: FUR-CH-10003199 | C8: 310.744 | D8: 4 | E8: 0.3 | F8: -26.6352
A9: CA-2017-151750 | B9: OFF-AR-10003158 | C9: 12.736 | D9: 4 | E9: 0.2 | F9: 2.2288
A10: CA-2017-151750 | B10: OFF-BI-10000301 | C10: 6.47 | D10: 5 | E10: 0.8 | F10: -9.705
A11: CA-2017-151750 | B11: OFF-BI-10000343 | C11: 13.748 | D11: 14 | E11: 0.8 | F11: -22.6842
A12: CA-2017-151750 | B12: OFF-AP-10004708 | C12: 15.224 | D12: 2 | E12: 0.8 | F12: -38.8212
A13: CA-2017-113481 | B13: TEC-MA-10002178 | C13: 695.7 | D13: 2 | E13: 0.5 | F13: -27.828
A14: CA-2017-113481 | B14: OFF-BI-10003694 | C14: 15.66 | D14: 5 | E14: 0.7 | F14: -12.528
A15: CA-2017-113481 | B15: OFF-BI-10000474 | C15: 28.854 | D15: 6 | E15: 0.7 | F15: -21.1596
A16: CA-2017-147207 | B16: OFF-AR-10001955 | C16: 31.744 | D16: 2 | E16: 0.2 | F16: 3.968
... A157: CA-2017-157273 | B157: TEC-PH-10002275 | C157: 604.768 | D157: 4 | E157: 0.2 | F157: 60.4768

Sheet Pivot Table 1
A1: Sales by Region
A2: Region and Categories | B2: Sum of Sales
A3: Central | B3: 21690.656
A4: East | B4: 5383.284
A5: South | B5: 4815.59
A6: West | B6: 12081.844
A7: Grand Total | B7: 43971.374

Sheet Pivot Table 2
A1: Sales by Product Category and Sub-Category
A2: Category and Sub-Category | B2: Total Sales | C2: Total Profit
A3: Office Supplies | B3: 21274.289 | C3: 3260.4467
A4: Technology | B4: 16733.053 | C4: 3919.4326
A5: Furniture | B5: 5964.032 | C5: -39.4402
A6: Grand Total | B6: 43971.374 | C6: 7140.4391

Sheet Pivot Table 3
A1: Customer Segment Performance Analysis
B2: Regions
B3: Central | E3: East | H3: South | K3: West | N3: Total Total Sales | O3: Total Avg Sale per Order | P3: Total Order Count
A4: Segment | B4: Total Sales | C4: Avg Sale per Order | D4: Order Count | E4: Total Sales | F4: Avg Sale per Order | G4: Order Count | H4: Total Sales | I4: Avg Sale per Order | J4: Order Count | K4: Total Sales | L4: Avg Sale per Order | M4: Order Count
A5: Consumer | B5: 11074.039 | C5: 346.06372 | D5: 32 | E5: 4647.768 | F5: 232.3884 | G5: 20 | H5: 3635.014 | I5: 302.91783 | J5: 12 | K5: 3855.02 | L5: 226.76588 | M5: 17 | N5: 23211.841 | O5: 286.56594 | P5: 81
A6: Corporate | B6: 9014.484 | C6: 600.9656 | D6: 15 | E6: 207.846 | F6: 207.846 | G6: 1 | H6: 762.844 | I6: 152.5688 | J6: 5 | K6: 2236.058 | L6: 159.71843 | M6: 14 | N6: 12221.232 | O6: 349.17806 | P6: 35
A7: Home Office | B7: 1602.133 | C7: 114.43807 | D7: 14 | E7: 527.67 | F7: 175.89 | G7: 3 | H7: 417.732 | I7: 139.244 | J7: 3 | K7: 5990.766 | L7: 315.30347 | M7: 19 | N7: 8538.301 | O7: 218.93079 | P7: 39
A8: Grand Total | B8: 21690.656 | C8: 355.58452 | D8: 61 | E8: 5383.284 | F8: 224.3035 | G8: 24 | H8: 4815.59 | I8: 240.7795 | J8: 20 | K8: 12081.844 | L8: 241.63688 | M8: 50 | N8: 43971.374 | O8: 283.68628 | P8: 155

Sheet Dashboard

Sheet Insights and Recommendations
